[2025-07-27T06:08:32.636+0000] {local_task_job_runner.py:120} INFO - ::group::Pre task execution logs
[2025-07-27T06:08:32.672+0000] {taskinstance.py:2076} INFO - Dependencies all met for dep_context=non-requeueable deps ti=<TaskInstance: hw2_ml_pipeline.run_full_pipeline manual__2025-07-27T06:08:32+00:00 [queued]>
[2025-07-27T06:08:32.681+0000] {taskinstance.py:2076} INFO - Dependencies all met for dep_context=requeueable deps ti=<TaskInstance: hw2_ml_pipeline.run_full_pipeline manual__2025-07-27T06:08:32+00:00 [queued]>
[2025-07-27T06:08:32.682+0000] {taskinstance.py:2306} INFO - Starting attempt 1 of 1
[2025-07-27T06:08:32.695+0000] {taskinstance.py:2330} INFO - Executing <Task(DockerOperator): run_full_pipeline> on 2025-07-27 06:08:32+00:00
[2025-07-27T06:08:32.703+0000] {logging_mixin.py:188} WARNING - /home/***/.local/lib/python3.12/site-packages/***/task/task_runner/standard_task_runner.py:62 DeprecationWarning: This process (pid=183) is multi-threaded, use of fork() may lead to deadlocks in the child.
[2025-07-27T06:08:32.705+0000] {standard_task_runner.py:64} INFO - Started process 184 to run task
[2025-07-27T06:08:32.703+0000] {standard_task_runner.py:90} INFO - Running: ['***', 'tasks', 'run', 'hw2_ml_pipeline', 'run_full_pipeline', 'manual__2025-07-27T06:08:32+00:00', '--job-id', '9', '--raw', '--subdir', 'DAGS_FOLDER/ml_pipeline_dag.py', '--cfg-path', '/tmp/tmpo3up8n5h']
[2025-07-27T06:08:32.705+0000] {standard_task_runner.py:91} INFO - Job 9: Subtask run_full_pipeline
[2025-07-27T06:08:32.725+0000] {logging_mixin.py:188} WARNING - /home/***/.local/lib/python3.12/site-packages/***/settings.py:195 DeprecationWarning: The sql_alchemy_conn option in [core] has been moved to the sql_alchemy_conn option in [database] - the old setting has been used, but please update your config.
[2025-07-27T06:08:32.774+0000] {task_command.py:426} INFO - Running <TaskInstance: hw2_ml_pipeline.run_full_pipeline manual__2025-07-27T06:08:32+00:00 [running]> on host eb3a3660026c
[2025-07-27T06:08:32.866+0000] {taskinstance.py:2648} INFO - Exporting env vars: AIRFLOW_CTX_DAG_OWNER='***' AIRFLOW_CTX_DAG_ID='hw2_ml_pipeline' AIRFLOW_CTX_TASK_ID='run_full_pipeline' AIRFLOW_CTX_EXECUTION_DATE='2025-07-27T06:08:32+00:00' AIRFLOW_CTX_TRY_NUMBER='1' AIRFLOW_CTX_DAG_RUN_ID='manual__2025-07-27T06:08:32+00:00'
[2025-07-27T06:08:32.867+0000] {taskinstance.py:430} INFO - ::endgroup::
[2025-07-27T06:08:32.950+0000] {docker.py:367} INFO - Starting docker container from image 4de89279943ea0e42ef94b23123347ac714c2e6b47774d13be052f8c7e4031ab-ml-pipeline
[2025-07-27T06:08:32.958+0000] {taskinstance.py:441} INFO - ::group::Post task execution logs
[2025-07-27T06:08:32.959+0000] {taskinstance.py:2905} ERROR - Task failed with exception
Traceback (most recent call last):
  File "/home/airflow/.local/lib/python3.12/site-packages/docker/api/client.py", line 275, in _raise_for_status
    response.raise_for_status()
  File "/home/airflow/.local/lib/python3.12/site-packages/requests/models.py", line 1024, in raise_for_status
    raise HTTPError(http_error_msg, response=self)
requests.exceptions.HTTPError: 400 Client Error: Bad Request for url: http+docker://localhost/v1.50/containers/create

The above exception was the direct cause of the following exception:

Traceback (most recent call last):
  File "/home/airflow/.local/lib/python3.12/site-packages/airflow/models/taskinstance.py", line 465, in _execute_task
    result = _execute_callable(context=context, **execute_callable_kwargs)
             ^^^^^^^^^^^^^^^^^^^^^^^^^^^^^^^^^^^^^^^^^^^^^^^^^^^^^^^^^^^^^
  File "/home/airflow/.local/lib/python3.12/site-packages/airflow/models/taskinstance.py", line 432, in _execute_callable
    return execute_callable(context=context, **execute_callable_kwargs)
           ^^^^^^^^^^^^^^^^^^^^^^^^^^^^^^^^^^^^^^^^^^^^^^^^^^^^^^^^^^^^
  File "/home/airflow/.local/lib/python3.12/site-packages/airflow/models/baseoperator.py", line 401, in wrapper
    return func(self, *args, **kwargs)
           ^^^^^^^^^^^^^^^^^^^^^^^^^^^
  File "/home/airflow/.local/lib/python3.12/site-packages/airflow/providers/docker/operators/docker.py", line 513, in execute
    return self._run_image()
           ^^^^^^^^^^^^^^^^^
  File "/home/airflow/.local/lib/python3.12/site-packages/airflow/providers/docker/operators/docker.py", line 372, in _run_image
    return self._run_image_with_mounts([*self.mounts, tmp_mount], add_tmp_variable=True)
           ^^^^^^^^^^^^^^^^^^^^^^^^^^^^^^^^^^^^^^^^^^^^^^^^^^^^^^^^^^^^^^^^^^^^^^^^^^^^^
  File "/home/airflow/.local/lib/python3.12/site-packages/airflow/providers/docker/operators/docker.py", line 399, in _run_image_with_mounts
    self.container = self.cli.create_container(
                     ^^^^^^^^^^^^^^^^^^^^^^^^^^
  File "/home/airflow/.local/lib/python3.12/site-packages/docker/api/container.py", line 440, in create_container
    return self.create_container_from_config(config, name, platform)
           ^^^^^^^^^^^^^^^^^^^^^^^^^^^^^^^^^^^^^^^^^^^^^^^^^^^^^^^^^
  File "/home/airflow/.local/lib/python3.12/site-packages/docker/api/container.py", line 457, in create_container_from_config
    return self._result(res, True)
           ^^^^^^^^^^^^^^^^^^^^^^^
  File "/home/airflow/.local/lib/python3.12/site-packages/docker/api/client.py", line 281, in _result
    self._raise_for_status(response)
  File "/home/airflow/.local/lib/python3.12/site-packages/docker/api/client.py", line 277, in _raise_for_status
    raise create_api_error_from_http_exception(e) from e
          ^^^^^^^^^^^^^^^^^^^^^^^^^^^^^^^^^^^^^^^
  File "/home/airflow/.local/lib/python3.12/site-packages/docker/errors.py", line 39, in create_api_error_from_http_exception
    raise cls(e, response=response, explanation=explanation) from e
docker.errors.APIError: 400 Client Error for http+docker://localhost/v1.50/containers/create: Bad Request ("invalid mount config for type "bind": bind source path does not exist: /opt/data")
[2025-07-27T06:08:32.969+0000] {taskinstance.py:1206} INFO - Marking task as FAILED. dag_id=hw2_ml_pipeline, task_id=run_full_pipeline, run_id=manual__2025-07-27T06:08:32+00:00, execution_date=20250727T060832, start_date=20250727T060832, end_date=20250727T060832
[2025-07-27T06:08:32.978+0000] {standard_task_runner.py:110} ERROR - Failed to execute job 9 for task run_full_pipeline (400 Client Error for http+docker://localhost/v1.50/containers/create: Bad Request ("invalid mount config for type "bind": bind source path does not exist: /opt/data"); 184)
[2025-07-27T06:08:32.999+0000] {local_task_job_runner.py:243} INFO - Task exited with return code 1
[2025-07-27T06:08:33.014+0000] {taskinstance.py:3503} INFO - 0 downstream tasks scheduled from follow-on schedule check
[2025-07-27T06:08:33.017+0000] {local_task_job_runner.py:222} INFO - ::endgroup::
