[2025-07-29T01:12:39.100+0000] {local_task_job_runner.py:120} INFO - ::group::Pre task execution logs
[2025-07-29T01:12:39.122+0000] {taskinstance.py:2076} INFO - Dependencies all met for dep_context=non-requeueable deps ti=<TaskInstance: hw2_ml_pipeline.preprocess manual__2025-07-29T01:12:37.561258+00:00 [queued]>
[2025-07-29T01:12:39.127+0000] {taskinstance.py:2076} INFO - Dependencies all met for dep_context=requeueable deps ti=<TaskInstance: hw2_ml_pipeline.preprocess manual__2025-07-29T01:12:37.561258+00:00 [queued]>
[2025-07-29T01:12:39.128+0000] {taskinstance.py:2306} INFO - Starting attempt 1 of 1
[2025-07-29T01:12:39.137+0000] {taskinstance.py:2330} INFO - Executing <Task(PythonOperator): preprocess> on 2025-07-29 01:12:37.561258+00:00
[2025-07-29T01:12:39.147+0000] {logging_mixin.py:188} WARNING - /home/***/.local/lib/python3.12/site-packages/***/task/task_runner/standard_task_runner.py:62 DeprecationWarning: This process (pid=253) is multi-threaded, use of fork() may lead to deadlocks in the child.
[2025-07-29T01:12:39.146+0000] {standard_task_runner.py:90} INFO - Running: ['***', 'tasks', 'run', 'hw2_ml_pipeline', 'preprocess', 'manual__2025-07-29T01:12:37.561258+00:00', '--job-id', '4', '--raw', '--subdir', 'DAGS_FOLDER/ml_pipeline_dag.py', '--cfg-path', '/tmp/tmpwop3yjc4']
[2025-07-29T01:12:39.149+0000] {standard_task_runner.py:64} INFO - Started process 270 to run task
[2025-07-29T01:12:39.149+0000] {standard_task_runner.py:91} INFO - Job 4: Subtask preprocess
[2025-07-29T01:12:39.167+0000] {logging_mixin.py:188} WARNING - /home/***/.local/lib/python3.12/site-packages/***/settings.py:195 DeprecationWarning: The sql_alchemy_conn option in [core] has been moved to the sql_alchemy_conn option in [database] - the old setting has been used, but please update your config.
[2025-07-29T01:12:39.219+0000] {task_command.py:426} INFO - Running <TaskInstance: hw2_ml_pipeline.preprocess manual__2025-07-29T01:12:37.561258+00:00 [running]> on host c0571b425e8d
[2025-07-29T01:12:39.284+0000] {taskinstance.py:2648} INFO - Exporting env vars: AIRFLOW_CTX_DAG_OWNER='***' AIRFLOW_CTX_DAG_ID='hw2_ml_pipeline' AIRFLOW_CTX_TASK_ID='preprocess' AIRFLOW_CTX_EXECUTION_DATE='2025-07-29T01:12:37.561258+00:00' AIRFLOW_CTX_TRY_NUMBER='1' AIRFLOW_CTX_DAG_RUN_ID='manual__2025-07-29T01:12:37.561258+00:00'
[2025-07-29T01:12:39.285+0000] {taskinstance.py:430} INFO - ::endgroup::
[2025-07-29T01:12:39.306+0000] {taskinstance.py:441} INFO - ::group::Post task execution logs
[2025-07-29T01:12:39.307+0000] {taskinstance.py:2905} ERROR - Task failed with exception
Traceback (most recent call last):
  File "/home/airflow/.local/lib/python3.12/site-packages/airflow/models/taskinstance.py", line 465, in _execute_task
    result = _execute_callable(context=context, **execute_callable_kwargs)
             ^^^^^^^^^^^^^^^^^^^^^^^^^^^^^^^^^^^^^^^^^^^^^^^^^^^^^^^^^^^^^
  File "/home/airflow/.local/lib/python3.12/site-packages/airflow/models/taskinstance.py", line 432, in _execute_callable
    return execute_callable(context=context, **execute_callable_kwargs)
           ^^^^^^^^^^^^^^^^^^^^^^^^^^^^^^^^^^^^^^^^^^^^^^^^^^^^^^^^^^^^
  File "/home/airflow/.local/lib/python3.12/site-packages/airflow/models/baseoperator.py", line 401, in wrapper
    return func(self, *args, **kwargs)
           ^^^^^^^^^^^^^^^^^^^^^^^^^^^
  File "/home/airflow/.local/lib/python3.12/site-packages/airflow/operators/python.py", line 235, in execute
    return_value = self.execute_callable()
                   ^^^^^^^^^^^^^^^^^^^^^^^
  File "/home/airflow/.local/lib/python3.12/site-packages/airflow/operators/python.py", line 252, in execute_callable
    return self.python_callable(*self.op_args, **self.op_kwargs)
           ^^^^^^^^^^^^^^^^^^^^^^^^^^^^^^^^^^^^^^^^^^^^^^^^^^^^^
  File "/opt/airflow/dags/ml_pipeline_dag.py", line 28, in task_preprocess
    X_train, X_test, y_train, y_test = preprocess_data(DATA_PATH)
                                       ^^^^^^^^^^^^^^^^^^^^^^^^^^
  File "/opt/airflow/src/data_preprocessing.py", line 16, in preprocess_data
    df = pd.read_csv(path, keep_default_na=False)
         ^^^^^^^^^^^^^^^^^^^^^^^^^^^^^^^^^^^^^^^^
  File "/home/airflow/.local/lib/python3.12/site-packages/pandas/io/parsers/readers.py", line 948, in read_csv
    return _read(filepath_or_buffer, kwds)
           ^^^^^^^^^^^^^^^^^^^^^^^^^^^^^^^
  File "/home/airflow/.local/lib/python3.12/site-packages/pandas/io/parsers/readers.py", line 611, in _read
    parser = TextFileReader(filepath_or_buffer, **kwds)
             ^^^^^^^^^^^^^^^^^^^^^^^^^^^^^^^^^^^^^^^^^^
  File "/home/airflow/.local/lib/python3.12/site-packages/pandas/io/parsers/readers.py", line 1448, in __init__
    self._engine = self._make_engine(f, self.engine)
                   ^^^^^^^^^^^^^^^^^^^^^^^^^^^^^^^^^
  File "/home/airflow/.local/lib/python3.12/site-packages/pandas/io/parsers/readers.py", line 1705, in _make_engine
    self.handles = get_handle(
                   ^^^^^^^^^^^
  File "/home/airflow/.local/lib/python3.12/site-packages/pandas/io/common.py", line 863, in get_handle
    handle = open(
             ^^^^^
FileNotFoundError: [Errno 2] No such file or directory: '/opt/airflow/data/global_student_migration.csv'
[2025-07-29T01:12:39.323+0000] {taskinstance.py:1206} INFO - Marking task as FAILED. dag_id=hw2_ml_pipeline, task_id=preprocess, run_id=manual__2025-07-29T01:12:37.561258+00:00, execution_date=20250729T011237, start_date=20250729T011239, end_date=20250729T011239
[2025-07-29T01:12:39.333+0000] {standard_task_runner.py:110} ERROR - Failed to execute job 4 for task preprocess ([Errno 2] No such file or directory: '/opt/airflow/data/global_student_migration.csv'; 270)
[2025-07-29T01:12:39.364+0000] {local_task_job_runner.py:243} INFO - Task exited with return code 1
[2025-07-29T01:12:39.381+0000] {taskinstance.py:3503} INFO - 0 downstream tasks scheduled from follow-on schedule check
[2025-07-29T01:12:39.384+0000] {local_task_job_runner.py:222} INFO - ::endgroup::
